Workbook

Sheet Executive Summary
A1: Tata Steel Ltd. — Integrated Three-Statement Model
A2: Consolidated | ₹ crore unless otherwise stated | P2: Method | Q2: Implied Price
P3: DCF - Perpetuity | Q3: ='DCF Valuation'!B47 -> 86.89
A4: Project objective | B4: Build a source-backed operating model linking historical performance, forecast drivers, statements and checks. | P4: DCF - Exit Multiple | Q4: ='Trading Comps'!B35 -> 164.44
A5: Historical period | B5: FY2022–FY2026 | P5: Comps - EV/EBITDA | Q5: ='Trading Comps'!B36 -> 207.93
A6: Forecast period | B6: FY2027E–FY2031E | P6: Comps - EV/tonne | Q6: ='Trading Comps'!B37 -> 195.22
A7: Company | B7: Tata Steel Limited — Consolidated | P7: Current Price | Q7: 188.45
A8: Model stage | B8: Integrated three-statement, valuation and credit underwriting model
A9: Next build | B9: FY2026A baseline | Q1 FY2027 calibration | FY2027E-FY2031E | P9: Year | Q9: Net Debt / EBITDA | R9: FY29E | S9: FY30E | T9: FY31E
A10: Primary sources | B10: Tata Steel Integrated Reports / Annual Accounts | P10: FY27E | Q10: ='Credit Underwriting'!B13 -> 1.941704 | R10: ='Credit Underwriting'!D13 -> 1.4616 | S10: ='Credit Underwriting'!E13 -> 1.1494215 | T10: ='Credit Underwriting'!F13 -> 0.8375198
A11: Use cases | B11: Financial modelling, DCF valuation, credit underwriting | P11: FY28E | Q11: ='Credit Underwriting'!C13 -> 1.6898906
A12: Units | B12: ₹ crore; production/deliveries in MT | P12: FY29E | Q12: ='Credit Underwriting'!D13 -> 1.4616
P13: FY30E | Q13: ='Credit Underwriting'!E13 -> 1.1494215
P14: FY31E | Q14: ='Credit Underwriting'!F13 -> 0.8375198
A15: Historical Performance Snapshot
A16: Metric | B16: FY2022 | C16: FY2023 | D16: FY2024 | E16: FY2025 | F16: FY2026
A17: Revenue / Turnover | B17: 243959 | C17: 243353 | D17: 229171 | E17: 218543 | F17: 232140
A18: EBITDA | B18: 63830 | C18: 32698 | D18: 23402 | E18: 25802 | F18: 34848
A19: EBITDA Margin | B19: =B18/B17 -> 0.26164233 | C19: =C18/C17 -> 0.13436448 | D19: =D18/D17 -> 0.10211589 | E19: =E18/E17 -> 0.11806372 | F19: =F18/F17 -> 0.15011631
A20: Reported PAT | B20: 41749 | C20: 8075 | D20: -4910 | E20: 3174 | F20: 10886
A21: Production (MT) | B21: 31.03 | C21: 30.65 | D21: 29.94 | E21: 30.92 | F21: 31.67
A22: Deliveries (MT) | B22: 29.52 | C22: 28.79 | D22: 29.39 | E22: 30.96 | F22: 31.97
A25: Model Readiness
A26: Calculation integrity | B26: Mechanical checks expanded: BS tie, cash tie, debt tie, valuation sanity and downside covenant tests
A27: Decision readiness | B27: Public-source analytical model — assumptions and limitations are identified in the model and source register
A28: Why this matters | B28: Q1 FY27 actuals incorporated as a calibration checkpoint; peer market data should be refreshed before external use
A29: Source posture | B29: Headline historical metrics sourced to official Tata Steel annual reports.
A32: Valuation Snapshot
A33: Metric | B33: Value | C33: Metric | D33: Value | E33: Metric | F33: Value
A34: Current price | B34: ='DCF Valuation'!B69 -> 188.45 | C34: WACC | D34: ='DCF Valuation'!B30 -> 0.11714509 | E34: Terminal growth | F34: ='DCF Valuation'!B35 -> 0.03
A35: DCF - Perpetuity | B35: =ROUND('DCF Valuation'!B47,2) -> 86.89 | C35: DCF - Exit Multiple | D35: =ROUND('Trading Comps'!B35,2) -> 164.44 | E35: Reverse DCF g | F35: ='DCF Valuation'!B78 -> 0.068411405
A36: Comps - EV/EBITDA | B36: =ROUND('Trading Comps'!B36,2) -> 207.93 | C36: Comps - EV/tonne | D36: =ROUND('Trading Comps'!B37,2) -> 195.22 | E36: Peer median EV/EBITDA | F36: =ROUND('Trading Comps'!C13,2) -> 11.4
A37: Read-through | B37: Current price is above both DCF approaches and is supported primarily by normalized trading-comps evidence; reverse DCF shows the market requires substantially stronger terminal economics than the conservative base case.
A39: Credit Snapshot
A40: Q1 FY27 net debt | B40: 84173 | C40: Q1 FY27 liquidity | D40: 45950 | E40: FY27E net leverage | F40: ='Credit Underwriting'!B13 -> 1.941704
A42: Metric | B42: Base / FY27E | C42: Bear | D42: Liquidity Stress
A43: Maintenance DSCR | B43: ='Credit Underwriting'!B20 -> 1.7463421 | C43: ='Credit Underwriting'!J39 -> 0.77 | D43: ='Credit Underwriting'!J40 -> 0.8
A44: Net Debt / EBITDA | B44: ='Credit Underwriting'!B13 -> 1.941704 | C44: ='Credit Underwriting'!I39 -> 3.69 | D44: ='Credit Underwriting'!I40 -> 3.08
A45: Credit posture | B45: Proceed to diligence / conditional approval; contractual debt maturities and facility terms remain required.

Sheet Historicals
A1: Historical Operating Spread
A2: Tata Steel Consolidated | FY2022–FY2026
A4: Metric | B4: FY2022A | C4: FY2023A | D4: FY2024A | E4: FY2025A | F4: FY2026A
A6: Operating Metrics
A7: Production (MT) | B7: 31.03 | C7: 30.65 | D7: 29.94 | E7: 30.92 | F7: 31.67
A8: Deliveries (MT) | B8: 29.52 | C8: 28.79 | D8: 29.39 | E8: 30.96 | F8: 31.97
A9: Delivery growth | C9: =C8/B8-1 -> -0.024728997 | D9: =D8/C8-1 -> 0.02084057 | E9: =E8/D8-1 -> 0.05341953 | F9: =F8/E8-1 -> 0.032622739
A10: Turnover | B10: 243959 | C10: 243353 | D10: 229171 | E10: 218543 | F10: 232140
A11: Revenue growth | C11: =C10/B10-1 -> -0.002484024 | D11: =D10/C10-1 -> -0.058277482 | E11: =E10/D10-1 -> -0.04637585 | F11: =F10/E10-1 -> 0.062216589
A12: Revenue / tonne (₹/t) | B12: =B10/B8*10000000 -> 8.2641938e+10 | C12: =C10/C8*10000000 -> 8.4526919e+10 | D12: =D10/D8*10000000 -> 7.7975842e+10 | E12: =E10/E8*10000000 -> 7.0588824e+10 | F12: =F10/F8*10000000 -> 7.2611824e+10
A13: EBITDA | B13: 63830 | C13: 32698 | D13: 23402 | E13: 25802 | F13: 34848
A14: EBITDA margin | B14: =B13/B10 -> 0.26164233 | C14: =C13/C10 -> 0.13436448 | D14: =D13/D10 -> 0.10211589 | E14: =E13/E10 -> 0.11806372 | F14: =F13/F10 -> 0.15011631
A15: Reported PAT | B15: 41749 | C15: 8075 | D15: -4910 | E15: 3174 | F15: 10886
A18: Balance Sheet / Cash Flow Headline Metrics
A19: Net debt | B19: 51049 | C19: 67810 | E19: 82579 | F19: 80144
A20: Net debt / EBITDA | B20: =B19/B13 -> 0.799765 | C20: =C19/C13 -> 2.0738271 | D20: =IFERROR(D19/D13,"") -> 0 | E20: =E19/E13 -> 3.2004883 | F20: =F19/F13 -> 2.2998163
A21: Cash generated / operating cash flow | B21: 56283 | C21: 21683 | F21: 35064
A22: Capital expenditure | F22: 14559
A23: Free cash flow | B23: 27185 | F23: 10738

Sheet Assumptions
A1: Forecast Assumptions
A2: Editable inputs are blue text with yellow fill
A4: Driver | B4: FY2027E | C4: FY2028E | D4: FY2029E | E4: FY2030E | F4: FY2031E
A6: Operating Assumptions
A7: Delivery growth | B7: ='Operating Drivers'!C10 -> 0.025 | C7: ='Operating Drivers'!D10 -> 0.05 | D7: ='Operating Drivers'!E10 -> 0.04 | E7: ='Operating Drivers'!F10 -> 0.035 | F7: ='Operating Drivers'!G10 -> 0.03
A8: Revenue / tonne growth | B8: ='Operating Drivers'!C16 -> 0.035 | C8: ='Operating Drivers'!D16 -> 0.02 | D8: ='Operating Drivers'!E16 -> 0.02 | E8: ='Operating Drivers'!F16 -> 0.025 | F8: ='Operating Drivers'!G16 -> 0.025
A9: EBITDA margin | B9: ='Operating Drivers'!C19 -> 0.155 | C9: ='Operating Drivers'!D19 -> 0.16 | D9: ='Operating Drivers'!E19 -> 0.165 | E9: ='Operating Drivers'!F19 -> 0.17 | F9: ='Operating Drivers'!G19 -> 0.17
A10: D&A as % of revenue | B10: 0.055 | C10: 0.055 | D10: 0.055 | E10: 0.055 | F10: 0.055
A11: Effective tax rate | B11: 0.25 | C11: 0.25 | D11: 0.25 | E11: 0.25 | F11: 0.25
A12: Capex as % of revenue | B12: ='Capex Build'!C8 -> 0.081211176 | C12: ='Capex Build'!D8 -> 0.083410172 | D12: ='Capex Build'!E8 -> 0.082203566 | E12: ='Capex Build'!F8 -> 0.067379627 | F12: ='Capex Build'!G8 -> 0.057439417
A15: Working Capital / Financing Assumptions
A16: Net working capital as % of revenue | B16: 0.1 | C16: 0.1 | D16: 0.1 | E16: 0.1 | F16: 0.1
A17: Interest expense as % of opening net debt | B17: 0.07 | C17: 0.07 | D17: 0.07 | E17: 0.07 | F17: 0.07
A18: Dividend payout as % of PAT | B18: 0.3 | C18: 0.3 | D18: 0.3 | E18: 0.3 | F18: 0.3
A19: Minimum cash / liquidity assumption | B19: 13000 | C19: 13000 | D19: 13000 | E19: 13000 | F19: 13000
A20: Cash sweep % of excess cash | B20: 0.25 | C20: 0.3 | D20: 0.35 | E20: 0.4 | F20: 0.4
A21: Finance income yield on opening cash | B21: 0.04 | C21: 0.04 | D21: 0.04 | E21: 0.04 | F21: 0.04

Sheet Forecast
A1: Integrated Forecast Engine
A2: FY2027E–FY2031E | Simplified Phase 1 linkage
A4: Metric | B4: FY2022A | C4: FY2023A | D4: FY2024A | E4: FY2025A | F4: FY2026A | G4: FY2027E | H4: FY2028E | I4: FY2029E | J4: FY2030E | K4: FY2031E
A6: Income Statement
A7: Deliveries (MT) | B7: =Historicals!B8 -> 29.52 | C7: =Historicals!C8 -> 28.79 | D7: =Historicals!D8 -> 29.39 | E7: =Historicals!E8 -> 30.96 | F7: =Historicals!F8 -> 31.97 | G7: =F7*(1+Assumptions!B7) -> 32.76925 | H7: =G7*(1+Assumptions!C7) -> 34.407713 | I7: =H7*(1+Assumptions!D7) -> 35.784021 | J7: =I7*(1+Assumptions!E7) -> 37.036462 | K7: =J7*(1+Assumptions!F7) -> 38.147556
A8: Revenue / tonne (₹/t) | B8: =Historicals!B12 -> 8.2641938e+10 | C8: =Historicals!C12 -> 8.4526919e+10 | D8: =Historicals!D12 -> 7.7975842e+10 | E8: =Historicals!E12 -> 7.0588824e+10 | F8: =Historicals!F12 -> 7.2611824e+10 | G8: =F8*(1+Assumptions!B8) -> 7.5153237e+10 | H8: =G8*(1+Assumptions!C8) -> 7.6656302e+10 | I8: =H8*(1+Assumptions!D8) -> 7.8189428e+10 | J8: =I8*(1+Assumptions!E8) -> 8.0144164e+10 | K8: =J8*(1+Assumptions!F8) -> 8.2147768e+10
A9: Revenue | B9: =Historicals!B10 -> 243959 | C9: =Historicals!C10 -> 243353 | D9: =Historicals!D10 -> 229171 | E9: =Historicals!E10 -> 218543 | F9: =Historicals!F10 -> 232140 | G9: =G7*G8/10000000 -> 246271.52 | H9: =H7*H8/10000000 -> 263756.8 | I9: =I7*I8/10000000 -> 279793.21 | J9: =J7*J8/10000000 -> 296825.63 | K9: =K7*K8/10000000 -> 313373.65
A10: Revenue growth | C10: =C9/B9-1 -> -0.002484024 | D10: =D9/C9-1 -> -0.058277482 | E10: =E9/D9-1 -> -0.04637585 | F10: =F9/E9-1 -> 0.062216589 | G10: =G9/F9-1 -> 0.060875 | H10: =H9/G9-1 -> 0.071 | I10: =I9/H9-1 -> 0.0608 | J10: =J9/I9-1 -> 0.060875 | K10: =K9/J9-1 -> 0.05575
A11: EBITDA | B11: =Historicals!B13 -> 63830 | C11: =Historicals!C13 -> 32698 | D11: =Historicals!D13 -> 23402 | E11: =Historicals!E13 -> 25802 | F11: =Historicals!F13 -> 34848 | G11: =G9*Assumptions!B9 -> 38172.086 | H11: =H9*Assumptions!C9 -> 42201.088 | I11: =I9*Assumptions!D9 -> 46165.88 | J11: =J9*Assumptions!E9 -> 50460.356 | K11: =K9*Assumptions!F9 -> 53273.521
A12: EBITDA margin | B12: =Historicals!B14 -> 0.26164233 | C12: =Historicals!C14 -> 0.13436448 | D12: =Historicals!D14 -> 0.10211589 | E12: =Historicals!E14 -> 0.11806372 | F12: =Historicals!F14 -> 0.15011631 | G12: =G11/G9 -> 0.155 | H12: =H11/H9 -> 0.16 | I12: =I11/I9 -> 0.165 | J12: =J11/J9 -> 0.17 | K12: =K11/K9 -> 0.17
A13: D&A | G13: =G9*Assumptions!B10 -> 13544.934 | H13: =H9*Assumptions!C10 -> 14506.624 | I13: =I9*Assumptions!D10 -> 15388.627 | J13: =J9*Assumptions!E10 -> 16325.409 | K13: =K9*Assumptions!F10 -> 17235.551
A14: EBIT | G14: =G11-G13 -> 24627.152 | H14: =H11-H13 -> 27694.464 | I14: =I11-I13 -> 30777.254 | J14: =J11-J13 -> 34134.947 | K14: =K11-K13 -> 36037.97
A15: Interest expense | G15: =G29*Assumptions!B17 -> 5610.08 | H15: =H29*Assumptions!C17 -> 4769.7534 | I15: =I29*Assumptions!D17 -> 3879.2566 | J15: =J29*Assumptions!E17 -> 2840.6148 | K15: =K29*Assumptions!F17 -> 1375.2676
A16: EBT | G16: =G14-G15 -> 19017.072 | H16: =H14-H15 -> 22924.711 | I16: =I14-I15 -> 26897.997 | J16: =J14-J15 -> 31294.332 | K16: =K14-K15 -> 34662.703
A17: Taxes | G17: =MAX(0,G16*Assumptions!B11) -> 4754.2681 | H17: =MAX(0,H16*Assumptions!C11) -> 5731.1777 | I17: =MAX(0,I16*Assumptions!D11) -> 6724.4992 | J17: =MAX(0,J16*Assumptions!E11) -> 7823.583 | K17: =MAX(0,K16*Assumptions!F11) -> 8665.6757
A18: Net income | B18: =Historicals!B15 -> 41749 | C18: =Historicals!C15 -> 8075 | D18: =Historicals!D15 -> -4910 | E18: =Historicals!E15 -> 3174 | F18: =Historicals!F15 -> 10886 | G18: =G16-G17 -> 14262.804 | H18: =H16-H17 -> 17193.533 | I18: =I16-I17 -> 20173.498 | J18: =J16-J17 -> 23470.749 | K18: =K16-K17 -> 25997.027
A21: Cash Flow / Debt Bridge
A22: EBITDA | G22: =G11 -> 38172.086 | H22: =H11 -> 42201.088 | I22: =I11 -> 46165.88 | J22: =J11 -> 50460.356 | K22: =K11 -> 53273.521
A23: Cash taxes | G23: =-G17 -> -4754.2681 | H23: =-H17 -> -5731.1777 | I23: =-I17 -> -6724.4992 | J23: =-J17 -> -7823.583 | K23: =-K17 -> -8665.6757
A24: Change in NWC | G24: =-((G9*Assumptions!B16)-(F9*Assumptions!B16)) -> -1413.1522 | H24: =-((H9*Assumptions!C16)-(G9*Assumptions!B16)) -> -1748.5278 | I24: =-((I9*Assumptions!D16)-(H9*Assumptions!C16)) -> -1603.6413 | J24: =-((J9*Assumptions!E16)-(I9*Assumptions!D16)) -> -1703.2412 | K24: =-((K9*Assumptions!F16)-(J9*Assumptions!E16)) -> -1654.8029
A25: Capital expenditure | G25: =-G9*Assumptions!B12 -> -20000 | H25: =-H9*Assumptions!C12 -> -22000 | I25: =-I9*Assumptions!D12 -> -23000 | J25: =-J9*Assumptions!E12 -> -20000 | K25: =-K9*Assumptions!F12 -> -18000
A26: Free cash flow before financing | G26: =SUM(G22:G25) -> 12004.666 | H26: =SUM(H22:H25) -> 12721.383 | I26: =SUM(I22:I25) -> 14837.74 | J26: =SUM(J22:J25) -> 20933.532 | K26: =SUM(K22:K25) -> 24953.043
A27: Opening net debt
A28: Debt reduction / (increase)
A29: Closing net debt | G29: =Historicals!F19 -> 80144 | H29: =G31 -> 68139.334 | I29: =H31 -> 55417.952 | J29: =I31 -> 40580.212 | K29: =J31 -> 19646.68
G30: =MIN(G29,MAX(0,G26)) -> 12004.666 | H30: =MIN(H29,MAX(0,H26)) -> 12721.383 | I30: =MIN(I29,MAX(0,I26)) -> 14837.74 | J30: =MIN(J29,MAX(0,J26)) -> 20933.532 | K30: =MIN(K29,MAX(0,K26)) -> 19646.68
G31: =G29-G30 -> 68139.334 | H31: =H29-H30 -> 55417.952 | I31: =I29-I30 -> 40580.212 | J31: =J29-J30 -> 19646.68 | K31: =K29-K30 -> 0

Sheet Checks
A1: Model Checks
A2: Mechanical integrity checks; source completeness assessed separately
A4: Check | B4: Result | C4: Status
A5: FY2026 EBITDA margin agrees to historical | B5: =ABS(Forecast!F12-Historicals!F14) -> 0 | C5: =IF(B5<0.0001,"OK","CHECK") -> OK
A6: FY2026 PAT agrees to historical | B6: =ABS(Forecast!F18-Historicals!F15) -> 0 | C6: =IF(B6<1,"OK","CHECK") -> OK
A7: FY27 balance sheet balances | B7: =ABS('Balance Sheet'!D37) -> 0 | C7: =IF(B7<1,"OK","CHECK") -> OK
A8: FY28 balance sheet balances | B8: =ABS('Balance Sheet'!E37) -> 0 | C8: =IF(B8<1,"OK","CHECK") -> OK
A9: FY29 balance sheet balances | B9: =ABS('Balance Sheet'!F37) -> 0 | C9: =IF(B9<1,"OK","CHECK") -> OK
A10: FY30 balance sheet balances | B10: =ABS('Balance Sheet'!G37) -> 0 | C10: =IF(B10<1,"OK","CHECK") -> OK
A11: FY31 balance sheet balances | B11: =ABS('Balance Sheet'!H37) -> 0 | C11: =IF(B11<1,"OK","CHECK") -> OK
A12: FY27 cash flow ties to ending cash | B12: =ABS('Cash Flow'!D27-'Debt Schedule'!D11) -> 0 | C12: =IF(B12<1,"OK","CHECK") -> OK
A13: FY31 cash flow ties to ending cash | B13: =ABS('Cash Flow'!H27-'Debt Schedule'!H11) -> 0 | C13: =IF(B13<1,"OK","CHECK") -> OK
A14: FY27 net debt ties | B14: =ABS('Debt Schedule'!D13-('Debt Schedule'!D10-'Debt Schedule'!D11)) -> 0 | C14: =IF(B14<1,"OK","CHECK") -> OK
A15: Minimum cash maintained | B15: =MIN('Debt Schedule'!D11:H11) -> 13000 | C15: =IF(B15>=13000,"OK","CHECK") -> OK
A16: Base WACC exceeds terminal growth | B16: ='DCF Valuation'!B30-'DCF Valuation'!B35 -> 0.087145085 | C16: =IF(B16>0,"OK","CHECK") -> OK
A17: Reverse DCF implied g < WACC | B17: ='DCF Valuation'!B30-'DCF Valuation'!B78 -> 0.04873368 | C17: =IF(B17>0,"OK","CHECK") -> OK
A18: Bear leverage covenant headroom | B18: =3.5-'Credit Underwriting'!I39 -> -0.19 | C18: =IF(B18>=0,"OK","BREACH") -> BREACH
A19: Bear DSCR covenant headroom | B19: ='Credit Underwriting'!J39-1.5 -> -0.73 | C19: =IF(B19>=0,"OK","BREACH") -> BREACH
A20: Liquidity-stress DSCR headroom | B20: ='Credit Underwriting'!J40-1.5 -> -0.7 | C20: =IF(B20>=0,"OK","BREACH") -> BREACH
A21: DCF discount-factor linkage | B21: =ABS('DCF Valuation'!B14-(1/(1+'DCF Valuation'!B30))) -> 0 | C21: =IF(B21<0.000001,"OK","CHECK") -> OK
A22: Reverse DCF terminal-growth realism | B22: ='DCF Valuation'!B78 -> 0.068411405 | C22: =IF(B22<=0.04,"OK","STRETCH") -> STRETCH

Sheet Sources
A1: Source Register
A2: Official Tata Steel sources used in Phase 1
A4: Period | B4: Source | C4: Metrics used | D4: URL | E4: Notes
A5: FY2022 | B5: Integrated Report 2021-22 | C5: Turnover, EBITDA, PAT, production, deliveries, CFO, net debt | D5: https://www.tatasteel.com/investors/integrated-report-2021-22/index.html | E5: Official
A6: FY2023 | B6: Integrated Report 2022-23 | C6: Turnover, EBITDA, PAT, production, deliveries, CFO, net debt | D6: https://www.tatasteel.com/investors/integrated-report-2022-23/index.html | E6: Official
A7: FY2024 | B7: Integrated Report 2023-24 | C7: Turnover, EBITDA, PAT, production, deliveries | D7: https://www.tatasteel.com/investors/integrated-report-2023-24/performance-snapshot.html | E7: Official
A8: FY2025 | B8: Integrated Report 2024-25 | C8: Turnover, EBITDA, PAT, production, deliveries, net debt | D8: https://www.tatasteel.com/investors/integrated-report-2024-25/index.html | E8: Official
A9: FY2026 | B9: Integrated Report 2025-26 | C9: Turnover, EBITDA, PAT, production, deliveries, CFO, capex, FCF | D9: https://www.tatasteel.com/investors/integrated-report-2025-26/index.html | E9: Official
A12: FY2026 detailed P&L | B12: Tata Steel FY2026 consolidated financial results | C12: Revenue, EBITDA, finance costs, D&A, PBT, tax, PAT | D12: https://www.tatasteel.com/investors/financial-performance/financial-results/ | E12: Audited
A13: FY2026 balance sheet | B13: Tata Steel FY2026 consolidated financial results | C13: Assets, equity, borrowings, liabilities | D13: https://www.tatasteel.com/investors/integrated-reportannual-report/integrated-report-annual-accounts-2025-26-119th-year-and-related-documents/ | E13: Audited
A14: FY2026 cash flow | B14: Tata Steel FY2026 consolidated financial results | C14: CFO, capex, investing and financing cash flows | D14: https://www.tatasteel.com/investors/financial-performance/financial-results/ | E14: Audited
A15: FY2027 capex guidance | B15: Tata Steel FY2026 Financial Capital | C15: ~₹20,000 crore planned capex | D15: https://www.tatasteel.com/investors/integrated-report-2025-26/financial-capital.html | E15: Management guidance
A16: FY2026 leverage | B16: Tata Steel FY2026 Financial Capital | C16: Net debt ₹80,144 crore; net debt/EBITDA ~2.3x | D16: https://www.tatasteel.com/investors/integrated-report-2025-26/financial-capital.html | E16: Official company source
A19: FY26 capacity | B19: Tata Steel FY2026 Manufactured Capital | C19: 36 MTPA consolidated capacity; India/Europe asset base | D19: https://www.tatasteel.com/investors/integrated-report-2025-26/manufactured-capital.html | E19: Primary
... A51: WACC methodology | B51: Analyst calculation | C51: CAPM cost of equity + after-tax debt cost weighted using current market equity and FY26 gross debt | D51: Internal methodology | E51: Formula-driven

Sheet Income Statement
A1: Income Statement
A2: Tata Steel Consolidated | ₹ crore | Audited FY2025–FY2026 + forecast FY2027E–FY2031E
A4: Particulars | B4: FY2025A | C4: FY2026A | D4: FY2027E | E4: FY2028E | F4: FY2029E | G4: FY2030E | H4: FY2031E
A6: Revenue from operations | B6: 218542.51 | C6: 232139.94 | D6: =Forecast!G9 -> 246271.52 | E6: =Forecast!H9 -> 263756.8 | F6: =Forecast!I9 -> 279793.21 | G6: =Forecast!J9 -> 296825.63 | H6: =Forecast!K9 -> 313373.65
A7: EBITDA / segment result | B7: 25801.8 | C7: 34847.73 | D7: =Forecast!G11 -> 38172.086 | E7: =Forecast!H11 -> 42201.088 | F7: =Forecast!I11 -> 46165.88 | G7: =Forecast!J11 -> 50460.356 | H7: =Forecast!K11 -> 53273.521
A8: EBITDA margin | B8: =B7/B6 -> 0.11806307 | C8: =C7/C6 -> 0.15011518 | D8: =D7/D6 -> 0.155 | E8: =E7/E6 -> 0.16 | F8: =F7/F6 -> 0.165 | G8: =G7/G6 -> 0.17 | H8: =H7/H6 -> 0.17
A9: Finance income | B9: 1037.18 | C9: 906.49 | D9: =MAX(0,'Debt Schedule'!D15) -> 355.398 | E9: =MAX(0,'Debt Schedule'!E15) -> 520 | F9: =MAX(0,'Debt Schedule'!F15) -> 598.50278 | G9: =MAX(0,'Debt Schedule'!G15) -> 670.84516 | H9: =MAX(0,'Debt Schedule'!H15) -> 837.92714
A10: Finance costs | B10: -7340.95 | C10: -7167.06 | D10: =-'Debt Schedule'!D14 -> -5953.9473 | E10: =-'Debt Schedule'!E14 -> -6098.3224 | F10: =-'Debt Schedule'!F14 -> -6039.4453 | G10: =-'Debt Schedule'!G14 -> -5897.3027 | H10: =-'Debt Schedule'!H14 -> -5526.3877
A11: Depreciation & amortisation | B11: -10421.33 | C11: -11954.51 | D11: =-'PP&E Schedule'!D9 -> -11982.278 | E11: =-'PP&E Schedule'!E9 -> -12793.72 | F11: =-'PP&E Schedule'!F9 -> -13536.726 | G11: =-'PP&E Schedule'!G9 -> -14232.197 | H11: =-'PP&E Schedule'!H9 -> -14822.713
A12: EBIT | B12: =B7+B9+B10+B11 -> 9076.7 | C12: =C7+C9+C10+C11 -> 16632.65 | D12: =D7+D9+D10+D11 -> 20591.259 | E12: =E7+E9+E10+E11 -> 23829.046 | F12: =F7+F9+F10+F11 -> 27188.212 | G12: =G7+G9+G10+G11 -> 31001.702 | H12: =H7+H9+H10+H11 -> 33762.348
A13: Share of JV / associates | B13: 190.81 | C13: 368.5 | D13: 0 | E13: 0 | F13: 0 | G13: 0 | H13: 0
A14: Exceptional items | B14: -854.64 | C14: -1032.46 | D14: 0 | E14: 0 | F14: 0 | G14: 0 | H14: 0
A15: Profit before tax | B15: 8412.87 | C15: 15968.69 | D15: =SUM(D12:D14) -> 20591.259 | E15: =SUM(E12:E14) -> 23829.046 | F15: =SUM(F12:F14) -> 27188.212 | G15: =SUM(G12:G14) -> 31001.702 | H15: =SUM(H12:H14) -> 33762.348
A16: Tax expense | B16: -5239.09 | C16: -5082.87 | D16: =-MAX(0,D15*Assumptions!B11) -> -5147.8148 | E16: =-MAX(0,E15*Assumptions!C11) -> -5957.2615 | F16: =-MAX(0,F15*Assumptions!D11) -> -6797.053 | G16: =-MAX(0,G15*Assumptions!E11) -> -7750.4254 | H16: =-MAX(0,H15*Assumptions!F11) -> -8440.587
A17: Net profit | B17: 3173.78 | C17: 10885.82 | D17: =D15+D16 -> 15443.444 | E17: =E15+E16 -> 17871.784 | F17: =F15+F16 -> 20391.159 | G17: =G15+G16 -> 23251.276 | H17: =H15+H16 -> 25321.761

Sheet Balance Sheet
A1: Balance Sheet
A2: Tata Steel Consolidated | ₹ crore | Audited FY2025–FY2026 + forecast
A4: Particulars | B4: FY2025A | C4: FY2026A | D4: FY2027E | E4: FY2028E | F4: FY2029E | G4: FY2030E | H4: FY2031E
A6: Assets
A7: PP&E | B7: 125215.17 | C7: 149858.21 | D7: ='PP&E Schedule'!D13 -> 160792.62 | E7: ='PP&E Schedule'!E13 -> 170496.5 | F7: ='PP&E Schedule'!F13 -> 179844.27 | G7: ='PP&E Schedule'!G13 -> 188181.78 | H7: ='PP&E Schedule'!H13 -> 194644.73
A8: Capital work-in-progress | B8: 40601.88 | C8: 27501.29 | D8: ='PP&E Schedule'!D14 -> 24584.6 | E8: ='PP&E Schedule'!E14 -> 24087.002 | F8: ='PP&E Schedule'!F14 -> 24202.504 | G8: ='PP&E Schedule'!G14 -> 21632.801 | H8: ='PP&E Schedule'!H14 -> 18347.133
A9: Right-of-use assets | B9: 8087.95 | C9: 10072.66 | D9: =C9 -> 10072.66 | E9: =C9 -> 10072.66 | F9: =C9 -> 10072.66 | G9: =C9 -> 10072.66 | H9: =C9 -> 10072.66
A10: Goodwill & intangibles | B10: 18651.4 | C10: 21932.68 | D10: =C10 -> 21932.68 | E10: =C10 -> 21932.68 | F10: =C10 -> 21932.68 | G10: =C10 -> 21932.68 | H10: =C10 -> 21932.68
A11: Other non-current assets | B11: 18446.86 | C11: 19369.1 | D11: =C11 -> 19369.1 | E11: =C11 -> 19369.1 | F11: =C11 -> 19369.1 | G11: =C11 -> 19369.1 | H11: =C11 -> 19369.1
A12: Total non-current assets | B12: 211003.26 | C12: 228733.94 | D12: =SUM(D7:D11) -> 236751.66 | E12: =SUM(E7:E11) -> 245957.94 | F12: =SUM(F7:F11) -> 255421.22 | G12: =SUM(G7:G11) -> 261189.02 | H12: =SUM(H7:H11) -> 264366.31
A13: Inventories | B13: 44589.94 | C13: 47249.22 | D13: ='Working Capital'!D8 -> 49031.648 | E13: ='Working Capital'!E8 -> 51595.166 | F13: ='Working Capital'!F8 -> 53766.291 | G13: ='Working Capital'!G8 -> 56022.787 | H13: ='Working Capital'!H8 -> 58433.455
A14: Trade receivables | B14: 5260.06 | C14: 4916.89 | D14: ='Working Capital'!D10 -> 5397.732 | E14: ='Working Capital'!E10 -> 5780.971 | F14: ='Working Capital'!F10 -> 6132.454 | G14: ='Working Capital'!G10 -> 6505.7671 | H14: ='Working Capital'!H10 -> 6868.4637
A15: Cash & cash equivalents | B15: 9604.96 | C15: 8884.95 | D15: ='Debt Schedule'!D11 -> 13000 | E15: ='Debt Schedule'!E11 -> 14962.569 | F15: ='Debt Schedule'!F11 -> 16771.129 | G15: ='Debt Schedule'!G11 -> 20948.178 | H15: ='Debt Schedule'!H11 -> 25798.46
A16: Other current assets | B16: 8936.58 | C16: 11214.05 | D16: =C16 -> 11214.05 | E16: =C16 -> 11214.05 | F16: =C16 -> 11214.05 | G16: =C16 -> 11214.05 | H16: =C16 -> 11214.05
A17: Total current assets | B17: 68391.54 | C17: 72265.11 | D17: =SUM(D13:D16) -> 78643.43 | E17: =SUM(E13:E16) -> 83552.756 | F17: =SUM(F13:F16) -> 87883.924 | G17: =SUM(G13:G16) -> 94690.783 | H17: =SUM(H13:H16) -> 102314.43
A18: Assets held for sale | B18: 0 | C18: 255.06 | D18: 0 | E18: 0 | F18: 0 | G18: 0 | H18: 0
A19: Total assets | B19: 279394.8 | C19: 301254.11 | D19: =SUM(D12,D17,D18) -> 315395.09 | E19: =SUM(E12,E17,E18) -> 329510.7 | F19: =SUM(F12,F17,F18) -> 343305.14 | G19: =SUM(G12,G17,G18) -> 355879.8 | H19: =SUM(H12,H17,H18) -> 366680.74
A22: Equity & Liabilities
A23: Share capital | B23: 1247.44 | C23: 1247.44 | D23: =$C$23 -> 1247.44 | E23: =$C$23 -> 1247.44 | F23: =$C$23 -> 1247.44 | G23: =$C$23 -> 1247.44 | H23: =$C$23 -> 1247.44
A24: Other equity + NCI | B24: 90105.26 | C24: 102533.01 | D24: =C24+'Income Statement'!D17+'Cash Flow'!D21 -> 113343.42 | E24: =D24+'Income Statement'!E17+'Cash Flow'!E21 -> 125853.67 | F24: =E24+'Income Statement'!F17+'Cash Flow'!F21 -> 140127.48 | G24: =F24+'Income Statement'!G17+'Cash Flow'!G21 -> 156403.37 | H24: =G24+'Income Statement'!H17+'Cash Flow'!H21 -> 174128.61
A25: Total equity | B25: 91352.7 | C25: 103780.45 | D25: =SUM(D23:D24) -> 114590.86 | E25: =SUM(E23:E24) -> 127101.11 | F25: =SUM(F23:F24) -> 141374.92 | G25: =SUM(G23:G24) -> 157650.81 | H25: =SUM(H23:H24) -> 175376.05
A26: Non-current borrowings | B26: 68551.81 | C26: 63753.67 | D26: ='Debt Schedule'!D8 -> 65339.168 | E26: ='Debt Schedule'!E8 -> 64708.342 | F26: ='Debt Schedule'!F8 -> 63185.386 | G26: ='Debt Schedule'!G8 -> 59211.297 | H26: ='Debt Schedule'!H8 -> 52812.067
A27: Lease liabilities - non-current | B27: 4832.71 | C27: 6232.99 | D27: =$C$27 -> 6232.99 | E27: =$C$27 -> 6232.99 | F27: =$C$27 -> 6232.99 | G27: =$C$27 -> 6232.99 | H27: =$C$27 -> 6232.99
A28: Other non-current liabilities | B28: 28563.95 | C28: 30569.36 | D28: =$C$28 -> 30569.36 | E28: =$C$28 -> 30569.36 | F28: =$C$28 -> 30569.36 | G28: =$C$28 -> 30569.36 | H28: =$C$28 -> 30569.36
A29: Total non-current liabilities | B29: 101948.47 | C29: 100556.02 | D29: =SUM(D26:D28) -> 102141.52 | E29: =SUM(E26:E28) -> 101510.69 | F29: =SUM(F26:F28) -> 99987.736 | G29: =SUM(G26:G28) -> 96013.647 | H29: =SUM(H26:H28) -> 89614.417
A30: Current borrowings | B30: 20412 | C30: 21302.72 | D30: ='Debt Schedule'!D9 -> 21779.723 | E30: ='Debt Schedule'!E9 -> 21569.447 | F30: ='Debt Schedule'!F9 -> 21061.795 | G30: ='Debt Schedule'!G9 -> 19737.099 | H30: ='Debt Schedule'!H9 -> 17604.022
A31: Lease liabilities - current | B31: 1004.53 | C31: 1192.3 | D31: =$C$31 -> 1192.3 | E31: =$C$31 -> 1192.3 | F31: =$C$31 -> 1192.3 | G31: =$C$31 -> 1192.3 | H31: =$C$31 -> 1192.3
A32: Trade payables & acceptances | B32: 29314.38 | C32: 34610.14 | D32: ='Working Capital'!D12 -> 36488.668 | E32: ='Working Capital'!E12 -> 39455.127 | F32: ='Working Capital'!F12 -> 41604.868 | G32: ='Working Capital'!G12 -> 43873.267 | H32: ='Working Capital'!H12 -> 46319.202
A33: Other current liabilities | B33: 35362.64 | C33: 39812.48 | D33: =D19-D25-D29-D30-D31-D32 -> 39202.022 | E33: =E19-E25-E29-E30-E31-E32 -> 38682.022 | F33: =F19-F25-F29-F30-F31-F32 -> 38083.519 | G33: =G19-G25-G29-G30-G31-G32 -> 37412.674 | H33: =H19-H25-H29-H30-H31-H32 -> 36574.747
A34: Total current liabilities | B34: 86093.55 | C34: 96917.64 | D34: =SUM(D30:D33) -> 98662.713 | E34: =SUM(E30:E33) -> 100898.9 | F34: =SUM(F30:F33) -> 101942.48 | G34: =SUM(G30:G33) -> 102215.34 | H34: =SUM(H30:H33) -> 101690.27
A35: Total liabilities | B35: 188042.02 | C35: 197473.66 | D35: =D29+D34 -> 200804.23 | E35: =E29+E34 -> 202409.59 | F35: =F29+F34 -> 201930.22 | G35: =G29+G34 -> 198228.99 | H35: =H29+H34 -> 191304.69
A36: Total equity & liabilities | B36: 279394.72 | C36: 301254.11 | D36: =D25+D35 -> 315395.09 | E36: =E25+E35 -> 329510.7 | F36: =F25+F35 -> 343305.14 | G36: =G25+G35 -> 355879.8 | H36: =H25+H35 -> 366680.74
A37: Balance check | B37: =B19-B36 -> 0.08 | C37: =C19-C36 -> 0 | D37: =D19-D36 -> 0 | E37: =E19-E36 -> 0 | F37: =F19-F36 -> 0 | G37: =G19-G36 -> 0 | H37: =H19-H36 -> 0

Sheet Working Capital
A1: Working Capital Schedule
A2: Driver-based forecast | ₹ crore / days
A4: Metric | B4: FY2025A | C4: FY2026A | D4: FY2027E | E4: FY2028E | F4: FY2029E | G4: FY2030E | H4: FY2031E
A6: Revenue | B6: 218542.51 | C6: 232139.94 | D6: ='Income Statement'!D6 -> 246271.52 | E6: ='Income Statement'!E6 -> 263756.8 | F6: ='Income Statement'!F6 -> 279793.21 | G6: ='Income Statement'!G6 -> 296825.63 | H6: ='Income Statement'!H6 -> 313373.65
A7: Cash operating costs | B7: 192740.71 | C7: 197292.21 | D7: =D6-'Income Statement'!D7 -> 208099.44 | E7: =E6-'Income Statement'!E7 -> 221555.71 | F7: =F6-'Income Statement'!F7 -> 233627.33 | G7: =G6-'Income Statement'!G7 -> 246365.27 | H7: =H6-'Income Statement'!H7 -> 260100.13
A8: Inventory | B8: 44589.94 | C8: 47249.22 | D8: =D7*'Operating Drivers'!C26/365 -> 49031.648 | E8: =E7*'Operating Drivers'!D26/365 -> 51595.166 | F8: =F7*'Operating Drivers'!E26/365 -> 53766.291 | G8: =G7*'Operating Drivers'!F26/365 -> 56022.787 | H8: =H7*'Operating Drivers'!G26/365 -> 58433.455
A9: DIO | B9: =B8/B7*365 -> 84.44157 | C9: =C8/C7*365 -> 87.413311 | D9: ='Operating Drivers'!C26 -> 86 | E9: ='Operating Drivers'!D26 -> 85 | F9: ='Operating Drivers'!E26 -> 84 | G9: ='Operating Drivers'!F26 -> 83 | H9: ='Operating Drivers'!G26 -> 82
A10: Trade receivables | B10: 5260.06 | C10: 4916.89 | D10: =D6*'Operating Drivers'!C25/365 -> 5397.732 | E10: =E6*'Operating Drivers'!D25/365 -> 5780.971 | F10: =F6*'Operating Drivers'!E25/365 -> 6132.454 | G10: =G6*'Operating Drivers'!F25/365 -> 6505.7671 | H10: =H6*'Operating Drivers'!G25/365 -> 6868.4637
A11: DSO | B11: =B10/B6*365 -> 8.7851187 | C11: =C10/C6*365 -> 7.7309611 | D11: ='Operating Drivers'!C25 -> 8 | E11: ='Operating Drivers'!D25 -> 8 | F11: ='Operating Drivers'!E25 -> 8 | G11: ='Operating Drivers'!F25 -> 8 | H11: ='Operating Drivers'!G25 -> 8
A12: Trade payables & acceptances | B12: 29314.38 | C12: 34610.14 | D12: =D7*'Operating Drivers'!C27/365 -> 36488.668 | E12: =E7*'Operating Drivers'!D27/365 -> 39455.127 | F12: =F7*'Operating Drivers'!E27/365 -> 41604.868 | G12: =G7*'Operating Drivers'!F27/365 -> 43873.267 | H12: =H7*'Operating Drivers'!G27/365 -> 46319.202
A13: DPO | B13: =B12/B7*365 -> 55.513694 | C13: =C12/C7*365 -> 64.03041 | D13: ='Operating Drivers'!C27 -> 64 | E13: ='Operating Drivers'!D27 -> 65 | F13: ='Operating Drivers'!E27 -> 65 | G13: ='Operating Drivers'!F27 -> 65 | H13: ='Operating Drivers'!G27 -> 65
A14: Net operating working capital | B14: =B8+B10-B12 -> 20535.62 | C14: =C8+C10-C12 -> 17555.97 | D14: =D8+D10-D12 -> 17940.712 | E14: =E8+E10-E12 -> 17921.01 | F14: =F8+F10-F12 -> 18293.877 | G14: =G8+G10-G12 -> 18655.287 | H14: =H8+H10-H12 -> 18982.716
A15: Change in NWC | C15: =C14-B14 -> -2979.65 | D15: =D14-C14 -> 384.74174 | E15: =E14-D14 -> -19.701722 | F15: =F14-E14 -> 372.86685 | G15: =G14-F14 -> 361.41043 | H15: =H14-G14 -> 327.42916
A16: Cash release / (use) | C16: =-C15 -> 2979.65 | D16: =-D15 -> -384.74174 | E16: =-E15 -> 19.701722 | F16: =-F15 -> -372.86685 | G16: =-G15 -> -361.41043 | H16: =-H15 -> -327.42916

Sheet PP&E Schedule
A1: PP&E & Depreciation Schedule
A2: ₹ crore | capex and depreciation linked to assumptions
A4: Metric | B4: FY2025A | C4: FY2026A | D4: FY2027E | E4: FY2028E | F4: FY2029E | G4: FY2030E | H4: FY2031E
A6: Opening PP&E | C6: 125215.17 | D6: =C13 -> 149858.21 | E6: =D13 -> 160792.62 | F6: =E13 -> 170496.5 | G6: =F13 -> 179844.27 | H6: =G13 -> 188181.78
A7: Opening CWIP | C7: 40601.88 | D7: =C14 -> 27501.29 | E7: =D14 -> 24584.6 | F7: =E14 -> 24087.002 | G7: =F14 -> 24202.504 | H7: =G14 -> 21632.801
A8: Total capex | B8: 15670.52 | C8: 14559.05 | D8: ='Capex Build'!C7 -> 20000 | E8: ='Capex Build'!D7 -> 22000 | F8: ='Capex Build'!E7 -> 23000 | G8: ='Capex Build'!F7 -> 20000 | H8: ='Capex Build'!G7 -> 18000
A9: D&A | B9: 10421.33 | C9: 11954.51 | D9: =D6*7.5%+D10*3.75%+D12*3% -> 11982.278 | E9: =E6*7.5%+E10*3.75%+E12*3% -> 12793.72 | F9: =F6*7.5%+F10*3.75%+F12*3% -> 13536.726 | G9: =G6*7.5%+G10*3.75%+G12*3% -> 14232.197 | H9: =H6*7.5%+H10*3.75%+H12*3% -> 14822.713
A10: Maintenance capex | D10: ='Capex Build'!C10 -> 7388.1457 | E10: ='Capex Build'!D10 -> 7912.704 | F10: ='Capex Build'!E10 -> 8393.7964 | G10: ='Capex Build'!F10 -> 8904.7688 | H10: ='Capex Build'!G10 -> 9401.2096
A11: Expansion capex | D11: ='Capex Build'!C11 -> 12611.854 | E11: ='Capex Build'!D11 -> 14087.296 | F11: ='Capex Build'!E11 -> 14606.204 | G11: ='Capex Build'!F11 -> 11095.231 | H11: ='Capex Build'!G11 -> 8598.7904
A12: Capitalised expansion from CWIP | D12: =MIN(D7+D11,45%*D7+25%*D11) -> 15528.544 | E12: =MIN(E7+E11,45%*E7+25%*E11) -> 14584.894 | F12: =MIN(F7+F11,45%*F7+25%*F11) -> 14490.702 | G12: =MIN(G7+G11,45%*G7+25%*G11) -> 13664.935 | H12: =MIN(H7+H11,45%*H7+25%*H11) -> 11884.458
A13: Closing PP&E | B13: 125215.17 | C13: 149858.21 | D13: =D6+D10+D12-D9 -> 160792.62 | E13: =E6+E10+E12-E9 -> 170496.5 | F13: =F6+F10+F12-F9 -> 179844.27 | G13: =G6+G10+G12-G9 -> 188181.78 | H13: =H6+H10+H12-H9 -> 194644.73
A14: Closing CWIP | B14: 40601.88 | C14: 27501.29 | D14: =D7+D11-D12 -> 24584.6 | E14: =E7+E11-E12 -> 24087.002 | F14: =F7+F11-F12 -> 24202.504 | G14: =G7+G11-G12 -> 21632.801 | H14: =H7+H11-H12 -> 18347.133
A15: D&A / opening PP&E | C15: =C9/C6 -> 0.095471739 | D15: =D9/D6 -> 0.079957431 | E15: =E9/E6 -> 0.079566585 | F15: =F9/F6 -> 0.079395917 | G15: =G9/G6 -> 0.079136228 | H15: =H9/H6 -> 0.078768054
A16: PP&E + CWIP | B16: 165817.05 | C16: 177359.5 | D16: =D13+D14 -> 185377.22 | E16: =E13+E14 -> 194583.5 | F16: =F13+F14 -> 204046.78 | G16: =G13+G14 -> 209814.58 | H16: =H13+H14 -> 212991.87

Sheet Debt Schedule
A1: Debt Schedule
A2: ₹ crore | simplified debt roll-forward and interest schedule
A4: Metric | B4: FY2025A | C4: FY2026A | D4: FY2027E | E4: FY2028E | F4: FY2029E | G4: FY2030E | H4: FY2031E
A6: Opening borrowings | C6: 88963.81 | D6: =D19 -> 85056.39 | E6: =E19 -> 87118.891 | F6: =F19 -> 86277.79 | G6: =G19 -> 84247.182 | H6: =H19 -> 78948.396
A7: Debt issuance / (repayment) | B7: 5324.95 | C7: -9105.42 | D7: =D28-D30 -> 2062.5011 | E7: =E28-E30 -> -841.1012 | F7: =F28-F30 -> -2030.608 | G7: =G28-G30 -> -5298.7856 | H7: =H28-H30 -> -8532.307
A8: Non-current borrowings | B8: 68551.81 | C8: 63753.67 | D8: =D31*75% -> 65339.168 | E8: =E31*75% -> 64708.342 | F8: =F31*75% -> 63185.386 | G8: =G31*75% -> 59211.297 | H8: =H31*75% -> 52812.067
A9: Current borrowings | B9: 20412 | C9: 21302.72 | D9: =D31*25% -> 21779.723 | E9: =E31*25% -> 21569.447 | F9: =F31*25% -> 21061.795 | G9: =G31*25% -> 19737.099 | H9: =H31*25% -> 17604.022
A10: Total borrowings | B10: 88963.81 | C10: 85056.39 | D10: =D31 -> 87118.891 | E10: =E31 -> 86277.79 | F10: =F31 -> 84247.182 | G10: =G31 -> 78948.396 | H10: =H31 -> 70416.089
A11: Cash & equivalents | B11: 9604.96 | C11: 8884.95 | D11: =D32 -> 13000 | E11: =E32 -> 14962.569 | F11: =F32 -> 16771.129 | G11: =G32 -> 20948.178 | H11: =H32 -> 25798.46
A12: Net borrowings | B12: 79358.85 | C12: 76171.44 | D12: =D33 -> 74118.891 | E12: =E33 -> 71315.22 | F12: =F33 -> 67476.053 | G12: =G33 -> 58000.218 | H12: =H33 -> 44617.629
A13: Net debt reported | B13: 82579 | C13: 80144 | D13: =D33 -> 74118.891 | E13: =E33 -> 71315.22 | F13: =F33 -> 67476.053 | G13: =G33 -> 58000.218 | H13: =H33 -> 44617.629
A14: Finance cost | B14: 7340.95 | C14: 7167.06 | D14: =D35 -> 5953.9473 | E14: =E35 -> 6098.3224 | F14: =F35 -> 6039.4453 | G14: =G35 -> 5897.3027 | H14: =H35 -> 5526.3877
A15: Finance income | B15: 1037.18 | C15: 906.49 | D15: =D36 -> 355.398 | E15: =E36 -> 520 | F15: =F36 -> 598.50278 | G15: =G36 -> 670.84516 | H15: =H36 -> 837.92714
A18: Cash Retention & Debt Sweep Mechanics
A19: Opening gross debt | D19: =C10 -> 85056.39 | E19: =D31 -> 87118.891 | F19: =E31 -> 86277.79 | G19: =F31 -> 84247.182 | H19: =G31 -> 78948.396
A20: Opening cash | D20: =C11 -> 8884.95 | E20: =D32 -> 13000 | F20: =E32 -> 14962.569 | G20: =F32 -> 16771.129 | H20: =G32 -> 20948.178
A21: Cash flow from operations | D21: ='Cash Flow'!D15 -> 32639.529 | E21: ='Cash Flow'!E15 -> 36263.528 | F21: ='Cash Flow'!F15 -> 38995.961 | G21: ='Cash Flow'!G15 -> 42348.521 | H21: ='Cash Flow'!H15 -> 44505.505
A22: Capital expenditure | D22: ='Capex Build'!C7 -> 20000 | E22: ='Capex Build'!D7 -> 22000 | F22: ='Capex Build'!E7 -> 23000 | G22: ='Capex Build'!F7 -> 20000 | H22: ='Capex Build'!G7 -> 18000
A23: Dividends | D23: =MAX(0,'Income Statement'!D17*Assumptions!B18) -> 4633.0333 | E23: =MAX(0,'Income Statement'!E17*Assumptions!C18) -> 5361.5353 | F23: =MAX(0,'Income Statement'!F17*Assumptions!D18) -> 6117.3477 | G23: =MAX(0,'Income Statement'!G17*Assumptions!E18) -> 6975.3828 | H23: =MAX(0,'Income Statement'!H17*Assumptions!F18) -> 7596.5283
A24: Cash interest | D24: =D35 -> 5953.9473 | E24: =E35 -> 6098.3224 | F24: =F35 -> 6039.4453 | G24: =G35 -> 5897.3027 | H24: =H35 -> 5526.3877
A25: Pre-debt cash balance | D25: =D20+D21-D22-D23-D24 -> 10937.499 | E25: =E20+E21-E22-E23-E24 -> 15803.671 | F25: =F20+F21-F22-F23-F24 -> 18801.737 | G25: =G20+G21-G22-G23-G24 -> 26246.964 | H25: =H20+H21-H22-H23-H24 -> 34330.767
A26: Minimum cash | D26: =Assumptions!B19 -> 13000 | E26: =Assumptions!C19 -> 13000 | F26: =Assumptions!D19 -> 13000 | G26: =Assumptions!E19 -> 13000 | H26: =Assumptions!F19 -> 13000
A27: Excess / (deficit) cash | D27: =D25-D26 -> -2062.5011 | E27: =E25-E26 -> 2803.6707 | F27: =F25-F26 -> 5801.737 | G27: =G25-G26 -> 13246.964 | H27: =H25-H26 -> 21330.767
A28: New borrowing | D28: =MAX(0,-D27) -> 2062.5011 | E28: =MAX(0,-E27) -> 0 | F28: =MAX(0,-F27) -> 0 | G28: =MAX(0,-G27) -> 0 | H28: =MAX(0,-H27) -> 0
A29: Cash sweep % | D29: =Assumptions!B20 -> 0.25 | E29: =Assumptions!C20 -> 0.3 | F29: =Assumptions!D20 -> 0.35 | G29: =Assumptions!E20 -> 0.4 | H29: =Assumptions!F20 -> 0.4
A30: Optional debt repayment | D30: =MIN(D19+D28,MAX(0,D27)*D29) -> 0 | E30: =MIN(E19+E28,MAX(0,E27)*E29) -> 841.1012 | F30: =MIN(F19+F28,MAX(0,F27)*F29) -> 2030.608 | G30: =MIN(G19+G28,MAX(0,G27)*G29) -> 5298.7856 | H30: =MIN(H19+H28,MAX(0,H27)*H29) -> 8532.307
A31: Ending gross debt | D31: =D19+D28-D30 -> 87118.891 | E31: =E19+E28-E30 -> 86277.79 | F31: =F19+F28-F30 -> 84247.182 | G31: =G19+G28-G30 -> 78948.396 | H31: =H19+H28-H30 -> 70416.089
A32: Ending cash | D32: =D25+D28-D30 -> 13000 | E32: =E25+E28-E30 -> 14962.569 | F32: =F25+F28-F30 -> 16771.129 | G32: =G25+G28-G30 -> 20948.178 | H32: =H25+H28-H30 -> 25798.46
A33: Ending net debt | D33: =D31-D32 -> 74118.891 | E33: =E31-E32 -> 71315.22 | F33: =F31-F32 -> 67476.053 | G33: =G31-G32 -> 58000.218 | H33: =H31-H32 -> 44617.629
A34: Interest rate | D34: =Assumptions!B17 -> 0.07 | E34: =Assumptions!C17 -> 0.07 | F34: =Assumptions!D17 -> 0.07 | G34: =Assumptions!E17 -> 0.07 | H34: =Assumptions!F17 -> 0.07
A35: Finance cost | D35: =D19*D34 -> 5953.9473 | E35: =E19*E34 -> 6098.3224 | F35: =F19*F34 -> 6039.4453 | G35: =G19*G34 -> 5897.3027 | H35: =H19*H34 -> 5526.3877
A36: Finance income | D36: =D20*Assumptions!B21 -> 355.398 | E36: =E20*Assumptions!C21 -> 520 | F36: =F20*Assumptions!D21 -> 598.50278 | G36: =G20*Assumptions!E21 -> 670.84516 | H36: =H20*Assumptions!F21 -> 837.92714

Sheet Cash Flow
A1: Cash Flow Statement
A2: Tata Steel Consolidated | ₹ crore | Audited FY2025–FY2026 + forecast
A4: Particulars | B4: FY2025A | C4: FY2026A | D4: FY2027E | E4: FY2028E | F4: FY2029E | G4: FY2030E | H4: FY2031E
A6: Profit before tax | B6: 8412.87 | C6: 15968.69 | D6: ='Income Statement'!D15 -> 20591.259 | E6: ='Income Statement'!E15 -> 23829.046 | F6: ='Income Statement'!F15 -> 27188.212 | G6: ='Income Statement'!G15 -> 31001.702 | H6: ='Income Statement'!H15 -> 33762.348
A7: D&A | B7: 10421.33 | C7: 11954.51 | D7: ='PP&E Schedule'!D9 -> 11982.278 | E7: ='PP&E Schedule'!E9 -> 12793.72 | F7: ='PP&E Schedule'!F9 -> 13536.726 | G7: ='PP&E Schedule'!G9 -> 14232.197 | H7: ='PP&E Schedule'!H9 -> 14822.713
A8: Finance costs | B8: 7340.95 | C8: 7167.06 | D8: ='Debt Schedule'!D14 -> 5953.9473 | E8: ='Debt Schedule'!E14 -> 6098.3224 | F8: ='Debt Schedule'!F14 -> 6039.4453 | G8: ='Debt Schedule'!G14 -> 5897.3027 | H8: ='Debt Schedule'!H14 -> 5526.3877
A9: Finance income | B9: -1037.18 | C9: -906.49 | D9: =-'Debt Schedule'!D15 -> -355.398 | E9: =-'Debt Schedule'!E15 -> -520 | F9: =-'Debt Schedule'!F15 -> -598.50278 | G9: =-'Debt Schedule'!G15 -> -670.84516 | H9: =-'Debt Schedule'!H15 -> -837.92714
A10: Other non-cash / exceptional / JV adjustments | D10: 0 | E10: 0 | F10: 0 | G10: 0 | H10: 0
A11: Operating profit before WC | B11: 23929.02 | C11: 34218.74 | D11: =SUM(D6:D10) -> 38172.086 | E11: =SUM(E6:E10) -> 42201.088 | F11: =SUM(F6:F10) -> 46165.88 | G11: =SUM(G6:G10) -> 50460.356 | H11: =SUM(H6:H10) -> 53273.521
A12: Working capital changes | B12: 2207.02 | C12: 5442.28 | D12: ='Working Capital'!D16 -> -384.74174 | E12: ='Working Capital'!E16 -> 19.701722 | F12: ='Working Capital'!F16 -> -372.86685 | G12: ='Working Capital'!G16 -> -361.41043 | H12: ='Working Capital'!H16 -> -327.42916
A13: Cash generated from operations | B13: 26136.04 | C13: 39661.02 | D13: =SUM(D11:D12) -> 37787.344 | E13: =SUM(E11:E12) -> 42220.79 | F13: =SUM(F11:F12) -> 45793.013 | G13: =SUM(G11:G12) -> 50098.946 | H13: =SUM(H11:H12) -> 52946.092
A14: Taxes paid | B14: -2998.46 | C14: -4596.56 | D14: ='Income Statement'!D16 -> -5147.8148 | E14: ='Income Statement'!E16 -> -5957.2615 | F14: ='Income Statement'!F16 -> -6797.053 | G14: ='Income Statement'!G16 -> -7750.4254 | H14: ='Income Statement'!H16 -> -8440.587
A15: Cash flow from operations | B15: 23137.58 | C15: 35064.46 | D15: =SUM(D13:D14) -> 32639.529 | E15: =SUM(E13:E14) -> 36263.528 | F15: =SUM(F13:F14) -> 38995.961 | G15: =SUM(G13:G14) -> 42348.521 | H15: =SUM(H13:H14) -> 44505.505
A16: Capital expenditure | B16: -15670.52 | C16: -14559.05 | D16: =-'Capex Build'!C7 -> -20000 | E16: =-'Capex Build'!D7 -> -22000 | F16: =-'Capex Build'!E7 -> -23000 | G16: =-'Capex Build'!F7 -> -20000 | H16: =-'Capex Build'!G7 -> -18000
A17: Other investing activities | B17: 1872.02 | C17: -346.26 | D17: 0 | E17: 0 | F17: 0 | G17: 0 | H17: 0
A18: Cash flow from investing | B18: -13798.5 | C18: -14905.31 | D18: =SUM(D16:D17) -> -20000 | E18: =SUM(E16:E17) -> -22000 | F18: =SUM(F16:F17) -> -23000 | G18: =SUM(G16:G17) -> -20000 | H18: =SUM(H16:H17) -> -18000
A20: Debt issuance / (repayment) | B20: 5324.95 | C20: -9105.42 | D20: ='Debt Schedule'!D7 -> 2062.5011 | E20: ='Debt Schedule'!E7 -> -841.1012 | F20: ='Debt Schedule'!F7 -> -2030.608 | G20: ='Debt Schedule'!G7 -> -5298.7856 | H20: ='Debt Schedule'!H7 -> -8532.307
A21: Dividends paid | B21: -4489.87 | C21: -4487.87 | D21: =-MAX(0,'Income Statement'!D17*Assumptions!B18) -> -4633.0333 | E21: =-MAX(0,'Income Statement'!E17*Assumptions!C18) -> -5361.5353 | F21: =-MAX(0,'Income Statement'!F17*Assumptions!D18) -> -6117.3477 | G21: =-MAX(0,'Income Statement'!G17*Assumptions!E18) -> -6975.3828 | H21: =-MAX(0,'Income Statement'!H17*Assumptions!F18) -> -7596.5283
A22: Other financing / interest / lease | B22: -7837.52 | C22: -7793.83 | D22: =-'Debt Schedule'!D14 -> -5953.9473 | E22: =-'Debt Schedule'!E14 -> -6098.3224 | F22: =-'Debt Schedule'!F14 -> -6039.4453 | G22: =-'Debt Schedule'!G14 -> -5897.3027 | H22: =-'Debt Schedule'!H14 -> -5526.3877
A23: Cash flow from financing | B23: -7002.44 | C23: -21387.12 | D23: =SUM(D20:D22) -> -8524.4795 | E23: =SUM(E20:E22) -> -12300.959 | F23: =SUM(F20:F22) -> -14187.401 | G23: =SUM(G20:G22) -> -18171.471 | H23: =SUM(H20:H22) -> -21655.223
A24: FX effect | B24: 187.48 | C24: 507.96 | D24: 0 | E24: 0 | F24: 0 | G24: 0 | H24: 0
A25: Net change in cash | B25: 2524.12 | C25: -720.01 | D25: =D27-D26 -> 4115.05 | E25: =E27-E26 -> 1962.5695 | F25: =F27-F26 -> 1808.5596 | G25: =G27-G26 -> 4177.0494 | H25: =H27-H26 -> 4850.282
A26: Opening cash | B26: 7080.84 | C26: 9604.96 | D26: =C27 -> 8884.95 | E26: =D27 -> 13000 | F26: =E27 -> 14962.569 | G26: =F27 -> 16771.129 | H26: =G27 -> 20948.178
A27: Closing cash | B27: 9604.96 | C27: 8884.95 | D27: ='Debt Schedule'!D11 -> 13000 | E27: ='Debt Schedule'!E11 -> 14962.569 | F27: ='Debt Schedule'!F11 -> 16771.129 | G27: ='Debt Schedule'!G11 -> 20948.178 | H27: ='Debt Schedule'!H11 -> 25798.46
A28: Free cash flow before financing | B28: 7467.06 | C28: 20159.15 | D28: =D15+D18 -> 12639.529 | E28: =E15+E18 -> 14263.528 | F28: =F15+F18 -> 15995.961 | G28: =G15+G18 -> 22348.521 | H28: =H15+H18 -> 26505.505
A29: Dividends | B29: 4489.87 | C29: 4487.87 | D29: =-D21 -> 4633.0333 | E29: =-E21 -> 5361.5353 | F29: =-F21 -> 6117.3477 | G29: =-G21 -> 6975.3828 | H29: =-H21 -> 7596.5283
A30: Cash available after dividends | B30: 2977.19 | C30: 15671.28 | D30: =D28-D29 -> 8006.4962 | E30: =E28-E29 -> 8901.9931 | F30: =F28-F29 -> 9878.6128 | G30: =G28-G29 -> 15373.138 | H30: =H28-H29 -> 18908.977

Sheet Ratios
A1: Financial Ratios & Credit Metrics
A2: Profitability, liquidity, leverage and cash conversion
A4: Metric | B4: FY2025A | C4: FY2026A | D4: FY2027E | E4: FY2028E | F4: FY2029E | G4: FY2030E | H4: FY2031E
A6: Revenue growth | C6: ='Income Statement'!C6/'Income Statement'!B6-1 -> 0.062218696 | D6: ='Income Statement'!D6/'Income Statement'!C6-1 -> 0.060875274 | E6: ='Income Statement'!E6/'Income Statement'!D6-1 -> 0.071 | F6: ='Income Statement'!F6/'Income Statement'!E6-1 -> 0.0608 | G6: ='Income Statement'!G6/'Income Statement'!F6-1 -> 0.060875 | H6: ='Income Statement'!H6/'Income Statement'!G6-1 -> 0.05575
A7: EBITDA margin | B7: ='Income Statement'!B7/'Income Statement'!B6 -> 0.11806307 | C7: ='Income Statement'!C7/'Income Statement'!C6 -> 0.15011518 | D7: ='Income Statement'!D7/'Income Statement'!D6 -> 0.155 | E7: ='Income Statement'!E7/'Income Statement'!E6 -> 0.16 | F7: ='Income Statement'!F7/'Income Statement'!F6 -> 0.165 | G7: ='Income Statement'!G7/'Income Statement'!G6 -> 0.17 | H7: ='Income Statement'!H7/'Income Statement'!H6 -> 0.17
A8: Net margin | B8: ='Income Statement'!B17/'Income Statement'!B6 -> 0.014522484 | C8: ='Income Statement'!C17/'Income Statement'!C6 -> 0.046893352 | D8: ='Income Statement'!D17/'Income Statement'!D6 -> 0.062709014 | E8: ='Income Statement'!E17/'Income Statement'!E6 -> 0.067758573 | F8: ='Income Statement'!F17/'Income Statement'!F6 -> 0.07287939 | G8: ='Income Statement'!G17/'Income Statement'!G6 -> 0.078333116 | H8: ='Income Statement'!H17/'Income Statement'!H6 -> 0.080803733
A9: Net debt / EBITDA | B9: ='Debt Schedule'!B13/'Income Statement'!B7 -> 3.2005131 | C9: ='Debt Schedule'!C13/'Income Statement'!C7 -> 2.2998342 | D9: ='Debt Schedule'!D13/'Income Statement'!D7 -> 1.941704 | E9: ='Debt Schedule'!E13/'Income Statement'!E7 -> 1.6898906 | F9: ='Debt Schedule'!F13/'Income Statement'!F7 -> 1.4616 | G9: ='Debt Schedule'!G13/'Income Statement'!G7 -> 1.1494215 | H9: ='Debt Schedule'!H13/'Income Statement'!H7 -> 0.8375198
A10: Debt / EBITDA | B10: ='Debt Schedule'!B10/'Income Statement'!B7 -> 3.4479691 | C10: ='Debt Schedule'!C10/'Income Statement'!C7 -> 2.4408015 | D10: ='Debt Schedule'!D10/'Income Statement'!D7 -> 2.282267 | E10: ='Debt Schedule'!E10/'Income Statement'!E7 -> 2.0444447 | F10: ='Debt Schedule'!F10/'Income Statement'!F7 -> 1.8248798 | G10: ='Debt Schedule'!G10/'Income Statement'!G7 -> 1.5645628 | H10: ='Debt Schedule'!H10/'Income Statement'!H7 -> 1.321784
A11: Interest coverage | B11: ='Income Statement'!B7/'Debt Schedule'!B14 -> 3.5147767 | C11: ='Income Statement'!C7/'Debt Schedule'!C14 -> 4.8622071 | D11: ='Income Statement'!D7/'Debt Schedule'!D14 -> 6.4112234 | E11: ='Income Statement'!E7/'Debt Schedule'!E14 -> 6.9201143 | F11: ='Income Statement'!F7/'Debt Schedule'!F14 -> 7.6440597 | G11: ='Income Statement'!G7/'Debt Schedule'!G14 -> 8.5565145 | H11: ='Income Statement'!H7/'Debt Schedule'!H14 -> 9.639845
A12: Current ratio | B12: ='Balance Sheet'!B17/'Balance Sheet'!B34 -> 0.79438634 | C12: ='Balance Sheet'!C17/'Balance Sheet'!C34 -> 0.74563423 | D12: ='Balance Sheet'!D17/'Balance Sheet'!D34 -> 0.79709373 | E12: ='Balance Sheet'!E17/'Balance Sheet'!E34 -> 0.82808395 | F12: ='Balance Sheet'!F17/'Balance Sheet'!F34 -> 0.86209323 | G12: ='Balance Sheet'!G17/'Balance Sheet'!G34 -> 0.92638524 | H12: ='Balance Sheet'!H17/'Balance Sheet'!H34 -> 1.0061378
A13: CFO / EBITDA | B13: ='Cash Flow'!B15/'Income Statement'!B7 -> 0.89674286 | C13: ='Cash Flow'!C15/'Income Statement'!C7 -> 1.0062193 | D13: ='Cash Flow'!D15/'Income Statement'!D7 -> 0.85506277 | E13: ='Cash Flow'!E15/'Income Statement'!E7 -> 0.85930316 | F13: ='Cash Flow'!F15/'Income Statement'!F7 -> 0.84469223 | G13: ='Cash Flow'!G15/'Income Statement'!G7 -> 0.83924339 | H13: ='Cash Flow'!H15/'Income Statement'!H7 -> 0.83541512
A14: Capex / Revenue | B14: =-'Cash Flow'!B16/'Income Statement'!B6 -> 0.071704677 | C14: =-'Cash Flow'!C16/'Income Statement'!C6 -> 0.062716696 | D14: =-'Cash Flow'!D16/'Income Statement'!D6 -> 0.081211176 | E14: =-'Cash Flow'!E16/'Income Statement'!E6 -> 0.083410172 | F14: =-'Cash Flow'!F16/'Income Statement'!F6 -> 0.082203566 | G14: =-'Cash Flow'!G16/'Income Statement'!G6 -> 0.067379627 | H14: =-'Cash Flow'!H16/'Income Statement'!H6 -> 0.057439417
A15: FCF / EBITDA | B15: ='Cash Flow'!B28/'Income Statement'!B7 -> 0.28940074 | C15: ='Cash Flow'!C28/'Income Statement'!C7 -> 0.57849249 | D15: ='Cash Flow'!D28/'Income Statement'!D7 -> 0.33111969 | E15: ='Cash Flow'!E28/'Income Statement'!E7 -> 0.33798959 | F15: ='Cash Flow'!F28/'Income Statement'!F7 -> 0.3464888 | G15: ='Cash Flow'!G28/'Income Statement'!G7 -> 0.44289264 | H15: ='Cash Flow'!H28/'Income Statement'!H7 -> 0.4975362

Sheet Operating Drivers
A1: Operating Driver Build
A2: Tata Steel Consolidated | FY2026A-FY2031E | volumes, realization and cost-cycle framework
A4: Driver | B4: FY2026A | C4: FY2027E | D4: FY2028E | E4: FY2029E | F4: FY2030E | G4: FY2031E
A6: Volume & Capacity
A7: Steelmaking capacity (MTPA) | B7: 36 | C7: 37 | D7: 38.5 | E7: 40 | F7: 42 | G7: 44
A8: Deliveries (MT) | B8: 31.97 | C8: =B8*(1+C10) -> 32.76925 | D8: =C8*(1+D10) -> 34.407713 | E8: =D8*(1+E10) -> 35.784021 | F8: =E8*(1+F10) -> 37.036462 | G8: =F8*(1+G10) -> 38.147556
A9: Implied utilization / delivery-to-capacity | B9: =B8/B7 -> 0.88805556 | C9: =C8/C7 -> 0.88565541 | D9: =D8/D7 -> 0.89370682 | E9: =E8/E7 -> 0.89460053 | F9: =F8/F7 -> 0.88182052 | G9: =G8/G7 -> 0.8669899
A10: Delivery growth | C10: 0.025 | D10: 0.05 | E10: 0.04 | F10: 0.035 | G10: 0.03
A11: Rationale | B11: Reported consolidated capacity; India expansions and EAF ramp-up | C11: India demand upcycle; Kalinganagar/Ludhiana ramp | D11: Value-added mix and downstream ramp | E11: Moderating toward mid-cycle | F11: Normalized growth | G11: Normalized growth
A14: Realization & Cost Cycle
A15: Revenue / tonne (₹/t) | B15: =Historicals!F12 -> 7.2611824e+10 | C15: =B15*(1+C16) -> 7.5153237e+10 | D15: =C15*(1+D16) -> 7.6656302e+10 | E15: =D15*(1+E16) -> 7.8189428e+10 | F15: =E15*(1+F16) -> 8.0144164e+10 | G15: =F15*(1+G16) -> 8.2147768e+10
A16: Realization growth | C16: 0.035 | D16: 0.02 | E16: 0.02 | F16: 0.025 | G16: 0.025
A17: Coking coal cost trend | B17: FY26 benefited from cost transformation | C17: +3% input pressure | D17: +1% | E17: 0% | F17: 0% | G17: 0%
A18: Iron ore exposure | B18: India 100% captive iron ore | C18: Captive benefit maintained | D18: Maintained | E18: Maintained | F18: Maintained | G18: Maintained
A19: EBITDA margin | B19: 0.1501 | C19: 0.155 | D19: 0.16 | E19: 0.165 | F19: 0.17 | G19: 0.17
A20: Cost transformation | B20: ₹10,868cr FY26 benefits | C20: ₹7,100cr additional target | D20: Partial structural retention | E20: Normalized | F20: Normalized | G20: Normalized
A21: Commentary | B21: Base case assumes volume-led growth, modest realization inflation and progressive margin normalization rather than peak-cycle pricing.
A24: Working Capital Drivers
A25: DSO (days) | B25: 8 | C25: 8 | D25: 8 | E25: 8 | F25: 8 | G25: 8
A26: Inventory days (cash operating cost) | B26: 87 | C26: 86 | D26: 85 | E26: 84 | F26: 83 | G26: 82
A27: DPO (days; cash operating cost) | B27: 64 | C27: 64 | D27: 65 | E27: 65 | F27: 65 | G27: 65
A28: Model rule | B28: Receivables use revenue; inventory/payables use cash operating cost (= Revenue - EBITDA). Forecast days remain near FY26 to avoid assuming working-capital improvement without evidence.
A30: Q1 FY27 Calibration
A31: Q1 FY27 consolidated revenue | B31: 60794
A32: Q1 FY27 consolidated EBITDA | B32: 9370
A33: Q1 FY27 EBITDA margin | B33: =B32/B31 -> 0.15412705
A34: Q1 FY27 deliveries (MT) | B34: 7.27
A35: Q1 FY27 net debt | B35: 84173
A36: Interpretation | B36: Q1 annualised revenue/EBITDA broadly supports the FY27 base case; maintenance shutdowns depressed volumes, while management expects normalisation in subsequent quarters.

Sheet DCF Valuation
A1: DCF Valuation
A2: FCFF | ₹ crore except per-share data | public-source assumptions
A4: FCFF Build | B4: FY2027E | C4: FY2028E | D4: FY2029E | E4: FY2030E | F4: FY2031E
A6: EBIT | B6: ='Income Statement'!D12 -> 20591.259 | C6: ='Income Statement'!E12 -> 23829.046 | D6: ='Income Statement'!F12 -> 27188.212 | E6: ='Income Statement'!G12 -> 31001.702 | F6: ='Income Statement'!H12 -> 33762.348
A7: Tax rate | B7: =Assumptions!B11 -> 0.25 | C7: =Assumptions!C11 -> 0.25 | D7: =Assumptions!D11 -> 0.25 | E7: =Assumptions!E11 -> 0.25 | F7: =Assumptions!F11 -> 0.25
A8: NOPAT | B8: =B6*(1-B7) -> 15443.444 | C8: =C6*(1-C7) -> 17871.784 | D8: =D6*(1-D7) -> 20391.159 | E8: =E6*(1-E7) -> 23251.276 | F8: =F6*(1-F7) -> 25321.761
A9: D&A | B9: ='PP&E Schedule'!D9 -> 11982.278 | C9: ='PP&E Schedule'!E9 -> 12793.72 | D9: ='PP&E Schedule'!F9 -> 13536.726 | E9: ='PP&E Schedule'!G9 -> 14232.197 | F9: ='PP&E Schedule'!H9 -> 14822.713
A10: Capital expenditure | B10: ='PP&E Schedule'!D8 -> 20000 | C10: ='PP&E Schedule'!E8 -> 22000 | D10: ='PP&E Schedule'!F8 -> 23000 | E10: ='PP&E Schedule'!G8 -> 20000 | F10: ='PP&E Schedule'!H8 -> 18000
A11: Change in NWC | B11: ='Working Capital'!D15 -> 384.74174 | C11: ='Working Capital'!E15 -> -19.701722 | D11: ='Working Capital'!F15 -> 372.86685 | E11: ='Working Capital'!G15 -> 361.41043 | F11: ='Working Capital'!H15 -> 327.42916
A12: FCFF | B12: =B8+B9-B10-B11 -> 7040.9802 | C12: =C8+C9-C10-C11 -> 8685.206 | D12: =D8+D9-D10-D11 -> 10555.018 | E12: =E8+E9-E10-E11 -> 17122.063 | F12: =F8+F9-F10-F11 -> 21817.044
A13: Discount period | B13: 1 | C13: 2 | D13: 3 | E13: 4 | F13: 5
A14: PV factor | B14: =1/(1+$B$30)^B13 -> 0.89513888 | C14: =1/(1+$B$30)^C13 -> 0.80127361 | D14: =1/(1+$B$30)^D13 -> 0.71725117 | E14: =1/(1+$B$30)^E13 -> 0.6420394 | F14: =1/(1+$B$30)^F13 -> 0.57471443
A15: PV of FCFF | B15: =B12*B14 -> 6302.6551 | C15: =C12*C14 -> 6959.2264 | D15: =D12*D14 -> 7570.599 | E15: =E12*E14 -> 10993.039 | F15: =F12*F14 -> 12538.57
A18: WACC
A19: Risk-free rate | B19: 0.0687
A20: Levered beta | B20: 1.13
A21: Equity risk premium | B21: 0.0606
A22: Cost of equity | B22: =B19+B20*B21 -> 0.137178
A23: Pre-tax cost of debt | B23: =-'Income Statement'!C10/AVERAGE('Debt Schedule'!B10,'Debt Schedule'!C10) -> 0.082370437
A24: Tax rate | B24: 0.25
A25: After-tax cost of debt | B25: =B23*(1-B24) -> 0.061777828
A26: Equity value / market cap | B26: =B31*B46 -> 235080.07
A27: Debt | B27: ='Debt Schedule'!C10 -> 85056.39
A28: E / V | B28: =B26/(B26+B27) -> 0.73431208
A29: D / V | B29: =B27/(B26+B27) -> 0.26568792
A30: WACC | B30: =B28*B22+B29*B25 -> 0.11714509
A31: Reference price | B31: 188.45
A34: Terminal Value & Equity Bridge
A35: Perpetual growth rate | B35: 0.03
A36: Terminal EV / EBITDA | B36: 8
A37: Terminal FCFF | B37: =F12 -> 21817.044
A38: Terminal EBITDA | B38: ='Income Statement'!H7 -> 53273.521
A39: TV - Perpetuity Growth | B39: =B37*(1+B35)/(B30-B35) -> 257863.72
A40: TV - Exit Multiple | B40: =B38*B36 -> 426188.17
A41: PV of explicit FCFF | B41: =SUM(B15:F15) -> 44364.09
A42: PV of TV - Perpetuity | B42: =B39*F14 -> 148198
A43: Enterprise Value - Perpetuity | B43: =B41+B42 -> 192562.09
A44: Less: Net debt | B44: 84173
A45: Equity Value - Perpetuity | B45: =B43-B44 -> 108389.09
A46: Diluted shares outstanding (crore) | B46: 1247.44
...

Sheet Trading Comps
A1: Trading Comparables
A2: India-focused peer screen | current market data around Aug 2026 | ₹ crore
A4: Company | B4: Market Cap | C4: Net Debt / debt proxy | D4: Enterprise Value | E4: FY26 Revenue | F4: Normalized EBITDA | G4: Production (MT) | H4: EV/EBITDA | I4: EV/tonne (₹) | J4: P/E
A5: Tata Steel | B5: 235080 | C5: 84173 | D5: =ROUND(B5+C5,0) -> 319253 | E5: 232140 | F5: 34848 | G5: 31.67 | H5: =ROUND(D5/F5,1) -> 9.2 | I5: =ROUND(D5/G5*10,0) -> 100806 | J5: 19.3
A6: JSW Steel | B6: 311808 | C6: 53870 | D6: =ROUND(B6+C6,0) -> 365678 | E6: 185470 | F6: 32048 | G6: 30.14 | H6: =ROUND(D6/F6,1) -> 11.4 | I6: =ROUND(D6/G6*10,0) -> 121326 | J6: 25.8
A7: Jindal Steel | B7: 115360 | C7: 3913 | D7: =ROUND(B7+C7,0) -> 119273 | E7: 53455 | F7: 9099 | G7: 9.25 | H7: =ROUND(D7/F7,1) -> 13.1 | I7: =ROUND(D7/G7*10,0) -> 128944 | J7: 37.4
A8: SAIL | B8: 71912 | C8: 31928 | D8: =ROUND(B8+C8,0) -> 103840 | E8: 110810 | F8: 13146 | G8: 19.43 | H8: =ROUND(D8/F8,1) -> 7.9 | I8: =ROUND(D8/G8*10,0) -> 53443 | J8: 14.9
A11: Peer Statistics — Excluding Tata Steel
A12: Metric | B12: Low | C12: Median | D12: High
A13: EV / EBITDA | B13: =ROUND(MIN(H6:H8),1) -> 7.9 | C13: =ROUND(MEDIAN(H6:H8),1) -> 11.4 | D13: =ROUND(MAX(H6:H8),1) -> 13.1
A14: EV / tonne | B14: =ROUND(MIN(I6:I8),0) -> 53443 | C14: =ROUND(MEDIAN(I6:I8),0) -> 121326 | D14: =ROUND(MAX(I6:I8),0) -> 128944
A15: P/E | B15: =ROUND(MIN(J6:J8),1) -> 14.9 | C15: =ROUND(MEDIAN(J6:J8),1) -> 25.8 | D15: =ROUND(MAX(J6:J8),1) -> 37.4
A16: Comment | B16: P/E is secondary due to exceptional items / capital structure differences; EV/EBITDA and EV/tonne are the primary cross-checks.
A19: Selected Trading Valuation — Normalized
A20: Metric | B20: Selected / Formula | C20: Rationale
A21: FY27E EBITDA | B21: ='Income Statement'!D7 -> 38172.086 | C21: Linked to operating model
A22: Selected EV / EBITDA | B22: 9 | C22: Discount to peer median to reflect Tata's European transition, cyclical normalization and execution risk
A23: Implied EV - EV/EBITDA | B23: =B21*B22 -> 343548.77
A24: FY27E production / delivery proxy (MT) | B24: =Forecast!G7 -> 32.76925 | C24: Uses forecast deliveries as throughput proxy
A25: Selected EV / tonne (₹) | B25: 100000 | C25: Close to Tata's current EV/tonne and below JSW/Jindal
A26: Implied EV - EV/tonne | B26: =B24*B25/10 -> 327692.5
A27: Latest net debt | B27: 84173 | C27: Q1 FY27 reported
A28: Implied equity value / share - EV/EBITDA | B28: =ROUND((B23-B27)/'DCF Valuation'!B46,2) -> 207.93
A29: Implied equity value / share - EV/tonne | B29: =ROUND((B26-B27)/'DCF Valuation'!B46,2) -> 195.22
A32: Valuation Football Field
A33: Method | B33: Implied ₹/share
A34: DCF - Perpetuity Growth | B34: =ROUND('DCF Valuation'!B47,2) -> 86.89
A35: DCF - Exit Multiple | B35: =ROUND(('DCF Valuation'!B41+'DCF Valuation'!B40*'DCF Valuation'!F14-'DCF Valuation'!B44)/'DCF Valuation'!B46,2) -> 164.44
A36: Trading Comps - EV/EBITDA | B36: =ROUND(B28,2) -> 207.93
A37: Trading Comps - EV/tonne | B37: =ROUND(B29,2) -> 195.22
A38: Current Market Price | B38: 188.45
A41: Source Notes
A42: Tata Steel | B42: Market price 26-Aug-2026; Q1 FY27 net debt; FY26 EBITDA/production
A43: JSW Steel | B43: Market cap approx. 18-Aug-2026; FY26 net debt ₹53,870cr; adjusted EBITDA ₹32,048cr; production 30.14MT
A44: Jindal Steel | B44: Market cap approx. 21-Aug-2026; FY26 adjusted EBITDA ₹9,099cr; production 9.25MT; net debt inferred from 0.43x ND/EBITDA
A45: SAIL | B45: Market cap approx. 21-25 Aug-2026; FY26 EBITDA ₹13,146cr; production 19.43MT; borrowings used as conservative net-debt proxy
A46: Comparability | B46: Peer dates and EBITDA definitions differ; use as a valuation range rather than a precise point estimate. Refresh market data before external circulation.

Sheet Credit Underwriting
A1: Credit Underwriting & Downside
A2: Lender case | ₹ crore | public-source screening model
A4: Metric | B4: FY2027E | C4: FY2028E | D4: FY2029E | E4: FY2030E | F4: FY2031E
